<mujoco model="Franka Reach">
<!-- =================================================
    Copyright 2020 Vikash Kumar
    Model   :: Franka Reach (MuJoCoV2.0)
    Author  :: Vikash Kumar (vikashplus@gmail.com)
    source  :: https://github.com/vikashplus/robohive
    License :: Under Apache License, Version 2.0 (the "License"); you may not use this file except in compliance with the License. You may obtain a copy of the License at http://www.apache.org/licenses/LICENSE-2.0 Unless required by applicable law or agreed to in writing, software distributed under the License is distributed on an "AS IS" BASIS, WITHOUT WARRANTIES OR CONDITIONS OF ANY KIND, either express or implied. See the License for the specific language governing permissions and limitations under the License.
====================================================== -->
    <compiler angle="radian" meshdir="../../../../simhive/franka_sim" texturedir="../../../../simhive/franka_sim"/>

    <size njmax='1000' nconmax='1000'/>

    <include file="../../../../simhive/scene_sim/topfloor_scene.xml"/>
    <include file="../../../../simhive/franka_sim/assets/assets.xml"/>
    <include file="../../../../simhive/franka_sim/assets/gripper_assets.xml"/>
    <include file="../../../../simhive/furniture_sim/simpleTable/simpleTable_asset.xml"/>
    <include file="../../../../simhive/franka_sim/assets/actuator0.xml"/>
    <include file="../../../../simhive/franka_sim/assets/gripper_actuator0.xml"/>

    <include file="../../../../simhive/YCB_sim/includes/defaults_ycb.xml"/>
    <include file="../../../../simhive/YCB_sim/includes/assets_004_sugar_box.xml"/>
    <include file="../../../../simhive/YCB_sim/includes/assets_003_cracker_box.xml"/>


    <worldbody>

        <camera name='left_cam' pos='-1.2 -0.5 1.8' quat='0.78 0.49 -0.22 -0.32'/>
        <camera name='right_cam' pos='1.2 -0.5 1.8' quat='0.76 0.5 0.21 0.35'/>
        <camera name='top_cam' pos='0 0.5 2.2' euler='0 0 0'/>
        <site name='workspace' type='box' size='.6 .375 .25' pos='0 0.475 1.0' group='3' rgba='0 0 .4 .2'/>

        <!-- Robot -->
        <body pos='0 0 .775' euler='0 0 1.57'>
            <geom type='cylinder' size='.120 .4' pos='-.04 0 -.4'/>
            <include file="../../../../simhive/franka_sim/assets/chain0.xml"/>
        </body>

        <!-- simple Table -->
        <body pos='0 0.475 0'>
            <include file="../../../../simhive/furniture_sim/simpleTable/simpleWoodTable_body.xml"/>
        </body>

        <!-- tasks details added here via include-->
        <site name='target' type='cylinder' size='.088 0.021' pos='0.4 0.5 0.78' group='1' rgba='.1 .8 .2 .4'/>

        <!-- object -->
        <body pos="0.0 0.5 .8">
            <include file="../../../../simhive/YCB_sim/includes/body_004_sugar_box.xml"/>
            <site name="sugarbox" size="0.01" pos="0 0 .088"/>
            <joint name="Tx" axis="1 0 0" type="slide" damping="0" limited="true" range="-1.0 1.0"/>
            <joint name="Ty" axis="0 1 0" type="slide" damping="0" limited="true" range="-0.5 0.5"/>
            <joint name="Tz" axis="0 0 1" type="slide" damping="0" limited="true" range="-1.0 1.0"/>
            <joint name="Rx" axis="1 0 0" type="hinge" damping="0" limited="true" range="-3.14 3.14"/>
            <joint name="Ry" axis="0 1 0" type="hinge" damping="0" limited="true" range="-3.14 3.14"/>
            <joint name="Rz" axis="0 0 1" type="hinge" damping="0" limited="true" range="-3.14 3.14"/>
        </body>

    </worldbody>

    <sensor>
        <jointpos name="Tx" joint="Tx"/>
        <jointpos name="Ty" joint="Ty"/>
        <jointpos name="Tz" joint="Tz"/>
        <jointpos name="Rx" joint="Rx"/>
        <jointpos name="Ry" joint="Ry"/>
        <jointpos name="Rz" joint="Rz"/>
    </sensor>

</mujoco>