<mujoco model="Adroit TableTop">
<!-- =================================================
    Copyright 2020 Vikash Kumar
    Model   :: Adroit TableTop (MuJoCoV2.1)
    Author  :: Vikash Kumar (vikashplus@gmail.com), Sudeep Dasari (sdasari@andrew.cmu.edu )
    Source  :: https://github.com/vikashplus/robohive
    License :: Under Apache License, Version 2.0 (the "License"); you may not use this file except in compliance with the License. You may obtain a copy of the License at http://www.apache.org/licenses/LICENSE-2.0 Unless required by applicable law or agreed to in writing, software distributed under the License is distributed on an "AS IS" BASIS, WITHOUT WARRANTIES OR CONDITIONS OF ANY KIND, either express or implied. See the License for the specific language governing permissions and limitations under the License.
====================================================== -->
    <compiler angle="radian" meshdir="../../../simhive/Adroit" texturedir="../../../simhive/Adroit"/>

    <size njmax='1000' nconmax='1000'/>

    <include file="../../../simhive/Adroit/resources/assets.xml"/>
    <include file="../../../simhive/furniture_sim/simpleTable/simpleTable_asset.xml"/>

    <worldbody>

        <!-- indoor lights -->
        <light directional="false" diffuse=".4 .4 .4" specular="0.4 0.4 0.4" pos="-4 -4 7" dir="1 1 -1"/>
        <light directional="false" diffuse=".4 .4 .4" specular="0.4 0.4 0.4" pos="4 -4 7" dir="-1 1 -1"/>
        <light directional="false" diffuse=".4 .4 .4" specular="0.4 0.4 0.4" pos="0 4 7" dir="0 -1 -1"/>

        <camera name='left_cam' pos='-1.2 -0.5 1.8' quat='0.78 0.49 -0.22 -0.32'/>
        <camera name='right_cam' pos='1.2 -0.5 1.8' quat='0.76 0.5 0.21 0.35'/>
        <camera name='center_cam' pos='0 2 1.8' euler="-1.2 0 3.14"/>
        <site name='workspace' type='box' size='.6 .375 .25' pos='0 0.475 1.0' group='3' rgba='0 0 .4 .2'/>

        <geom type="plane" rgba=".1 .1 .1 1" size="10 10 1" pos="0 0 -.76"/>

        <!-- Robot -->
        <body pos="0 -0.7 0.215" euler="-1.57 0 3.14">
            <inertial pos="0.001 -0.002 0.29" quat="0.982037 -0.0160006 0 -0.188007" mass="4" diaginertia="0.01 0.01 0.0075" />
            <!-- <joint name="ARTx" pos="0 0 0.396" axis="1 0 0" type="slide" range="-0.25 0.25" damping="20" limited="true"/>
            <joint name="ARTy" pos="0 0 0.396" axis="0 1 0" type="slide" range="-0.2 0.1" damping="20" limited="true"/>
            <joint name="ARTz" pos="0 0 0.396" axis="0 0 1" type="slide" range="-0.3 0.5" damping="20" limited="true"/>
            <joint name="ARRx" pos="0 0 0.396" axis="1 0 0" range="-1.75 1.75" damping="20" limited="true"/>
            <joint name="ARRy" pos="0 0 0.396" axis="0 1 0" range="-1.75 1.75" damping="20" limited="true"/>
            <joint name="ARRz" pos="0 0 0.396" axis="0 0 1" range="-2.5 2.5" damping="20" limited="true"/> -->
            <joint name="ARTx" pos="0 0 0" axis="1 0 0" type="slide" range="-0.25 0.35" damping="20" limited="true"/>
            <!-- <joint name="ARTy" pos="0 0 0" axis="0 1 0" type="slide" range="-0.2 0.1" damping="20" limited="true"/> -->
            <joint name="ARTy" pos="0 0 0" axis="0 1 0" type="slide" range="-0.2 0.3" damping="20" limited="true"/>
            <joint name="ARTz" pos="0 0 0" axis="0 0 1" type="slide" range="-0.3 0.5" damping="20" limited="true"/>
            <joint name="ARRx" pos="0 0 0" axis="1 0 0" range="-1.75 1.75" damping="20" limited="true"/>
            <joint name="ARRy" pos="0 0 0" axis="0 1 0" range="-1.75 1.75" damping="20" limited="true"/>
            <joint name="ARRz" pos="0 0 0" axis="0 0 1" range="-2.5 2.5" damping="20" limited="true"/>
            <include file="../../../simhive/Adroit/resources/chain.xml"/>
        </body>

        <!-- simple Table -->
        <body pos='0 0 -.76'>
            <include file="../../../simhive/furniture_sim/simpleTable/simpleGraniteTable_body.xml"/>
        </body>

        <!-- tasks details added here via include-->
        <site name='target' type='sphere' size='.03' pos='0 0 0.001' group='1' rgba='.1 .8 .2 .4'/>

    </worldbody>

    <actuator>
        <position name="A_ARTx" joint="ARTx" ctrllimited="true" ctrlrange="-0.25 0.35" kp="175" />
        <!-- <position name="A_ARTy" joint="ARTy" ctrllimited="true" ctrlrange="-0.2 0.1" kp="175" /> -->
        <position name="A_ARTy" joint="ARTy" ctrllimited="true" ctrlrange="-0.2 0.3" kp="175" />
        <position name="A_ARTz" joint="ARTz" ctrllimited="true" ctrlrange="-0.3 0.5" kp="175" />
        <position name="A_ARRx" joint="ARRx" ctrllimited="true" ctrlrange="-1.75 1.75" kp="150" />
        <position name="A_ARRy" joint="ARRy" ctrllimited="true" ctrlrange="-1.75 1.75" kp="150" />
        <position name="A_ARRz" joint="ARRz" ctrllimited="true" ctrlrange="-2.5 2.5" kp="150" />
    </actuator>
    <include file="../../../simhive/Adroit/resources/joint_position_actuation.xml"/>

</mujoco>
