<mujoco model="dkitty v2.0">
<!-- =========== Copyright | Vikash Kumar | vikashplus@gmail.com ==========================
  Model       :: dkitty walk v2.0
  Mujoco      :: Advanced physics simulation engine
    Source      : www.roboti.us
    Version     : 2.00
    Released    : 1Oct"18
  Author      :: Vikash Kumar
    Contacts    : vikashplus@gmail.com
    Last edits  : 19Jan'20, 30Apr16, 14Dec'15, 30Nov'15, 5Nov'15

Copyright 2020 Vikash Kumar: Licensed under Apache License, Version 2.0 (the "License")

You may not use this file except in compliance with the License. You may obtain a copy of
the License at http://www.apache.org/licenses/LICENSE-2.0 Unless required by applicable law
or agreed to in writing, software distributed under the License is distributed on an "AS IS"
BASIS, WITHOUT WARRANTIES OR CONDITIONS OF ANY KIND, either express or implied. See the License
for the specific language governing permissions and limitations under the License.
============================================================================================= -->

  <compiler angle="radian" meshdir="../../../simhive/robel_sim" texturedir="../../../simhive/robel_sim"/>
  <include file='../../../simhive/scene_sim/rooftop_scene.xml'/>
  <asset>
    <hfield name="hf1" size="4.5 4.5 1 .1" nrow="120" ncol="120"/>
  </asset>

  <sensor>
    <jointpos name="A:Tx" joint="A:Tx"/>
    <jointpos name="A:Ty" joint="A:Ty"/>
    <jointpos name="A:Tz" joint="A:Tz"/>
    <jointpos name="A:Rx" joint="A:Rx"/>
    <jointpos name="A:Ry" joint="A:Ry"/>
    <jointpos name="A:Rz" joint="A:Rz"/>
  </sensor>
  <include file="../../../simhive/robel_sim/dkitty/assets/dependenciesA_xh-v2.1.xml"/>

  <size njmax="1000" nconmax="1000"/>

  <worldbody>
    <!-- <geom name="target" pos="0 2 0" type="mesh" mesh="bulkhead_low_poly" rgba="1 0 0 1"/> -->
    <!-- <geom pos="0 -.45 0" name="robohive" type="mesh" mesh="robohive" conaffinity="0" contype="0" rgba=".3 .3 .3 1"/> -->
    <site name="target" pos="0 2 -.255" type="cylinder" size=".5 .005 0" rgba="0 1 0 .2"/>
    <site name="heading" pos="0 2 -.255" type="cylinder" size=".05 .25 0" rgba="1 1 0 1"/>
    <geom name="hfield1" type="hfield" hfield="hf1" pos="0 0 -.005" material="MatPlane" rgba=".7 .7 .7 1"/>

    <body name="A:frame" pos="0 0 0.315">
      <camera name="A:trackingZ" pos="0 0 3" zaxis="0 0 3" mode="trackcom"/>
      <camera name="A:trackingY" pos="1.5 1.5 .35" xyaxes="-.7 .7 0 0 -.3 1" mode="trackcom"/>
      <site name="torso" type="box" size=".090 .150 .007" group="4"/>
      <joint name="A:Tx" pos="0 0 0" axis="1 0 0" limited="true" type="slide" range="-5 5"/>
      <joint name="A:Ty" pos="0 0 0" axis="0 1 0" limited="true" type="slide" range="-5 5"/>
      <joint name="A:Tz" pos="0 0 0" axis="0 0 1" limited="true" type="slide" range="-2 2"/>
      <joint name="A:Rx" pos="0 0 0" axis="1 0 0" limited="true" range="-3.14 3.14"/>
      <joint name="A:Ry" pos="0 0 0" axis="0 1 0" limited="true" range="-3.14 3.14"/>
      <joint name="A:Rz" pos="0 0 0" axis="0 0 1" limited="true" range="-3.14 3.14"/>
      <include file="../../../simhive/robel_sim/dkitty/assets/chainA_xh-v2.1.xml"/>
    </body>

  </worldbody>

</mujoco>