<mujoco model="Index Thumb Model for turning key task">
    <compiler meshdir='../../../../sims/neuromuscular_sim/hand/'/>
    <include file="../../../../sims/neuromuscular_sim/hand/2nd_Hand_Model_full_hand_v0.1.4.xml"/>
    <default>
        <default class="key">
            <geom rgba=".6 .6 .5 1"/>
        </default>
    </default>

    <worldbody>
        <body name="key" pos="-.28 -.22 1.03" childclass="key" euler="0 0 .4">
            <geom type="ellipsoid" size=".030 .030 .004" name="keyhead"/>
            <geom type="capsule" size="0.005 0.070" pos="-.045 0 0" euler="0 1.57 0"/>
            <geom type="box" size=".015 .010 .004" pos="-.1 0.008 0"/>
            <joint axis="1 0 0" type="hinge" frictionloss="0.2"/>
            <site name="keyhead" size="0.005"/>
        </body>
    </worldbody>

    <keyframe>
        <key qpos='-1.571 0 0 0 0 0 0 0 0 0 0 0 0 0 0 0 0 0 0 0 0 0 0 -2.45045'/>
    </keyframe>
</mujoco>
