<mujoco model="Index Thumb Model for turning key task">
    <compiler meshdir='../../../../sims/neuromuscular_sim/hand/'/>
    <include file="../../../../sims/neuromuscular_sim/hand/Index_Thumb_v0.xml"/>
    <default>
        <default class="key">
            <geom rgba=".6 .6 .5 1"/>
        </default>
    </default>

    <worldbody>
        <body name="key" pos="-.14 -.06 .17" childclass="key" euler="0 0 .4">
            <geom type="ellipsoid" size=".030 .030 .004" name="keyhead"/>
            <geom type="capsule" size="0.005 0.070" pos="-.045 0 0" euler="0 1.57 0"/>
            <geom type="box" size=".015 .010 .004" pos="-.1 0.008 0"/>
            <joint axis="1 0 0" type="hinge" frictionloss="0.2"/>
            <site name="keyhead" size="0.005"/>
        </body>
    </worldbody>

    <keyframe>
        <key qpos='-0.017455 -0.174595 0.865249 0.882818 0.182 -0.031352 -0.17 0.592621 0'/>
    </keyframe>
</mujoco>