<mujoco model="franka_mocap_studyTable_buttons">

    <size njmax="1000" nconmax="1000"/>

    <include file="../../../../simhive/scene_sim/topfloor_scene.xml"/>
    <include file="../../../../simhive/franka_sim/assets/assets.xml"/>
    <include file="../../../../simhive/franka_sim/assets/gripper_assets.xml"/>
    <include file="../../../../simhive/franka_sim/assets/actuator0.xml"/>
    <include file="../../../../simhive/franka_sim/assets/gripper_actuator0.xml"/>
    <include file="../../../../simhive/furniture_sim/studyTable/studyTable_asset.xml"/>
    <include file="../../../../simhive/furniture_sim/lightButtons/lightButtons_assets.xml"/>

    <visual>
        <global offwidth="2560" offheight="1920" />
        <quality shadowsize="4096" offsamples="4" />
        <map force="0.1" fogend="5" />
    </visual>

    <compiler inertiafromgeom='auto' inertiagrouprange='3 5' angle="radian"
              meshdir="../../../../simhive/franka_sim"
              texturedir="../../../../simhive/franka_sim"/>

    <equality>
        <weld body1="vive_controller" body2="world" solref="0.02 1" solimp=".7 .95 0.050"/>
        <!-- <weld body1="vive_controller" body2="panda0_link7" solref="0.02 1" solimp=".4 .85 .1"/> -->
    </equality>

    <worldbody>

        <!-- Mocap -->
        <body name="vive_controller" mocap="true" pos="-0.440 -0.092 1.001" euler="-1.57 0 -.785">
            <geom type="box" group="2" pos="0 0 .142" size="0.02 0.10 0.03" contype="0" conaffinity="0" rgba=".9 .7 .95 .2" euler="0 0 -.785"/>
        </body>

        <site name="target" pos="0 0 0" size="0.1" rgba="0 2 0 .2"/>
        <camera name="left_cap" pos="-1.2 -0.5 1.8" quat="0.78 0.49 -0.22 -0.32" />
        <camera name="right_cap" pos="1.2 -0.5 1.8" quat="0.76 0.5 0.21 0.35"/>

        <!-- Robot -->
        <body name="chef" pos="0 0 .775" euler="0 0 1.57">
            <geom type="cylinder" size=".120 .4" pos="-.04 0 -.4"/>
            <include file="../../../../simhive/franka_sim/assets/chain0.xml"/>
        </body>

        <body name="desk" pos="-.375 -.4 0">
            <!-- Study Table -->
            <body pos="0 0.85 0">
                <include file="../../../../simhive/furniture_sim/studyTable/studyTable_body.xml"/>
            </body>

            <!-- Buttons -->
            <body pos="-.25 0.625 .76">
                <include file="../../../../simhive/furniture_sim/lightButtons/buttons_body.xml"/>
            </body>

            <!-- Lights -->
            <body pos="-.25 0.85 1.1">
                <include file="../../../../simhive/furniture_sim/lightButtons/lights_body.xml"/>
            </body>
        </body>

        <!-- Blocks -->
        <body name="bottle" pos="-.075 .6 0.775">
            <geom type="box" size="0.0401  0.0401 .14" rgba="0.9 0.9 0 1" pos="0 0 .14" group="4" mass=".240" contype="0" conaffinity="0"/> <!-- Inertial body-->
            <geom type="capsule"  size="0.0351 .095" rgba="0.8 0.6 0.8 1" pos="0 0 .135" mass="0.04"/>
            <geom type="cylinder" size="0.0351 .020" rgba="0.8 0.8 0.8 1" pos="0 0 .020" mass="0.04"/>
            <geom type="box" size="0.024 0.024 .022" rgba="0.8 0.8 0.8 1" pos="0 0 .020" mass="0.04"/>
            <geom type="cylinder" size="0.0150 .007" rgba="0.8 0.8 0.8 1" pos="0 0 .270" mass="0.04"/>
            <geom type="box" size=".01 .01 .01" rgba="0.8 0.8 0.8 1" pos="0 0 .020" mass="0.04"/> <!-- dummy -->
            <geom type="box" size=".01 .01 .01" rgba="0.8 0.8 0.8 1" pos="0 0 .020" mass="0.04"/> <!-- dummy -->

            <joint name="B1Tx" pos="0 0 0" axis="1 0 0" limited="true" type="slide" range="-1.5 1.5"/>
            <joint name="B1Ty" pos="0 0 0" axis="0 1 0" limited="true" type="slide" range="-1.5 1.5"/>
            <joint name="B1Tz" pos="0 0 0" axis="0 0 1" limited="true" type="slide" range="-1.5 1.5"/>
            <joint name="B1Rx" pos="0 0 0" axis="1 0 0" limited="true" type="hinge" range="-10.57 10.57"/>
            <joint name="B1Ry" pos="0 0 0" axis="0 1 0" limited="true" type="hinge" range="-10.57 10.57"/>
            <joint name="B1Rz" pos="0 0 0" axis="0 0 1" limited="true" type="hinge" range="-10.57 10.57"/>
        </body>
        <body name="glass" pos="0.075 .6 0.775">
            <geom type="box" size="0.0401  0.0401 .14" rgba="0.9 0.9 0 1" pos="0 0 .14" group="4" mass=".240" contype="0" conaffinity="0"/> <!-- Inertial body-->
            <geom type="box" size="0.0401  0.0401 .01" rgba="0.7 0.9 0.8 1" pos="0 0 .005" mass="0.04"/>
            <geom type="box" size=".01 .01 .001" rgba="0.7 0.9 0.8 1" pos="0 0 .005" mass="0.04"/> <!-- dummy -->
            <geom type="box" size=".01 .01 .001" rgba="0.7 0.9 0.8 1" pos="0 0 .005" mass="0.04"/> <!-- dummy -->
            <geom type="cylinder" size="0.0150 .025" rgba="0.7 0.9 0.8 1" pos="0 0 .035" mass="0.04"/>
            <geom type="capsule"  size="0.0351 .07"  rgba="0.7 0.9 0.8 1" pos="0 0 .16" mass="0.04"/>
            <geom type="cylinder" size="0.0351 .020" rgba="0.7 0.9 0.8 1" pos="0 0 .25" mass="0.04"/>

            <joint name="B2Tx" pos="0 0 0" axis="1 0 0" limited="true" type="slide" range="-1.5 1.5"/>
            <joint name="B2Ty" pos="0 0 0" axis="0 1 0" limited="true" type="slide" range="-1.5 1.5"/>
            <joint name="B2Tz" pos="0 0 0" axis="0 0 1" limited="true" type="slide" range="-1.5 1.5"/>
            <joint name="B2Rx" pos="0 0 0" axis="1 0 0" limited="true" type="hinge" range="-10.57 10.57"/>
            <joint name="B2Ry" pos="0 0 0" axis="0 1 0" limited="true" type="hinge" range="-10.57 10.57"/>
            <joint name="B2Rz" pos="0 0 0" axis="0 0 1" limited="true" type="hinge" range="-10.57 10.57"/>
        </body>
        <body name="mug" pos="-.255 .6 0.775" euler="0 0 -1.15">
            <geom type="box" size="0.055  0.055 .10" rgba="0.9 0.9 0 1" pos="0 0 .10" group="4" mass=".192" contype="0" conaffinity="0"/> <!-- Inertial body-->
            <geom type="box" size="0.030  0.030 .010" rgba="0.9 0.9 0 1" pos="0 0 .010" mass=".060"/>
            <geom type="capsule" size="0.0551 .040" rgba="0.9 0.9 0 1" pos="0 0 .095" mass=".060"/>
            <geom type="cylinder" size="0.0551 .030" rgba="0.9 0.9 0 1" pos="0 0 .165" mass=".060"/>
            <geom type="capsule" size="0.015 .050" rgba="0.9 0.9 0 1" pos="0.11 0 .100" mass=".004"/>
            <geom type="capsule" size="0.015 .035" rgba="0.9 0.9 0 1" pos="0.075 0 .05" euler="0 1.57 0" mass=".004"/>
            <geom type="capsule" size="0.015 .035" rgba="0.9 0.9 0 1" pos="0.075 0 .15" euler="0 1.57 0" mass=".004"/>
            <joint name="B3Tx" pos="0 0 0" axis="1 0 0" limited="true" type="slide" range="-1.5 1.5"/>
            <joint name="B3Ty" pos="0 0 0" axis="0 1 0" limited="true" type="slide" range="-1.5 1.5"/>
            <joint name="B3Tz" pos="0 0 0" axis="0 0 1" limited="true" type="slide" range="-1.5 1.5"/>
            <joint name="B3Rx" pos="0 0 0" axis="1 0 0" limited="true" type="hinge" range="-10.57 10.57"/>
            <joint name="B3Ry" pos="0 0 0" axis="0 1 0" limited="true" type="hinge" range="-10.57 10.57"/>
            <joint name="B3Rz" pos="0 0 0" axis="0 0 1" limited="true" type="hinge" range="-10.57 10.57"/>
        </body>

    </worldbody>

    <!-- <keyframe>
        <key qpos="0.16 -1.76 1.84 -2.51 0.36 0.79 1.55 0.00 0.00 0 0 -0.000135231 -0.000135231 -0.000135231 0.000217231 0.000217231 0.000217231 -0.315 -0.10 -0.110 1.57067 0 0 0 0 0 0 0 0 0 0 0 0 0 0"/>
        <key qpos="0.26 -1.76 1.84 -2.51 0.36 0.79 1.55 0.00 0.00 0 0 -0.000135231 -0.000135231 -0.000135231 0.000217231 0.000217231 0.000217231 -0.315 -0.10 -0.110 1.57067 0 0 0 0 0 0 0 0 0 0 0 0 0 0"/>
    </keyframe> -->

</mujoco>